Workbook
Name Bandwidth_List: Drived!$AR$4:$AR$20
Name Blank_List: Drived!$AS$4
Name Nonprd: 'Infra Requirements'!#REF!
Name Option1: KYA!$CF$21:$CF$36
Name Option2: KYA!$CG$21:$CG$36
Name Option3: KYA!$CH$21
Name Prod: 'Infra Requirements'!#REF!
Name RHEL: Drived!$V$1:$V$2
Name Ubuntu: Drived!$T$1:$T$3
Name vCPU_MongoDB: " =$BT$299:$BT$303"
Name vCPU_Redis: Drived!$AR$1:$AR$3
Name vCPU_Standard: Drived!$AH$1:$AH$6
Name Windows: Drived!$U$1:$U$7

Sheet Instructions
A1: # | B1: Purpose
A2: 1 | B2: The Purpose of this questionnaire is to gather the following application information to onboard them to National Government Cloud so that it works in a seamless manner
A3: 2 | B3: Infrastructure Requirements
A4: 3 | B4: Cloud Services Requirements
A5: 4 | B5: Architecture Insights
A6: 5 | B6: Decide the approach towards migration
A7: 6 | B7: Usage Patterns
A9: # | B9: Instructions
A10: 1 | B10: Kindly use one template per application/workload.
A11: 2 | B11: Kindly provide responses in a detailed manner
A12: 3 | B12: Kindly include architecture diagrams, any technical documents along with this workbook

Sheet KYA
A1: Know The Application
A2: The aim of this document is to gather comprehensive information about the application. Doing so will enable cloud solution architects to draft the architecture for the National Government Cloud accurately.
A3: Project Overview
A4: 1 | B4: Ministry Name*
A5: 2 | B5: Department Name *
A6: 3 | B6: Department Address *
A7: 4 | B7: Organization Name *
A8: 5 | B8: Project Name *
A10: Contact Details
A11: Sr. No. | B11: Role | C11: Name | D11: Designation | E11: Contact Number | F11: Email Address | G11: Location
A12: 1 | B12: Department Technical SPOC *
A13: 2 | B13: NIC Coordinator *
A14: 3 | B14: Application Owner/ User *
A15: 4 | B15: Application Support *
A17: Application Insight: Key Details Needed
B18: Questionnaires | F18: Response | G18: Remarks (If Any)
A19: Ques-1 | B19: Is this the new application you intend to deploy?
A20: Ques-2 | B20: If not, where is your current application hosted? **(Use "Remark" column if application hosted in "Other" location). | CF20: Bhubaneswar | CG20: Hyderabad | CH20: Clarification Required
A21: Ques-3 | B21: Would you like to migrate this application from the current hosted location? | CF21: Hyderabad | CG21: Bhubaneswar | CH21: Clarification Required
A22: Ques-4 | B22: Is this application accessible to the public (on the Internet)?
A23: Ques-5 | B23: How old is your application?
A24: Ques-6 | B24: If Application is Hosted on existing "NIC Cloud Hosting Model", then share the CUC Code (Cloud Unit Code)
A25: Ques-7 | B25: Is your application structured as monolithic or microservices-based
A26: Ques-8 | B26: What is the current data size (In GBs)?
A27: Ques-9 | B27: What is the Data growth "Quarter on Quarter"?
A28: Ques-10 | B28: What is the expected Compute growth "Quarter on Quarter"?
A29: Ques-11 | B29: What is the total number of users?
A30: Ques-12 | B30: What is the Concurrent number of users/Clients who are accessing the Application at the same time (simultaneous connection)?
A31: Ques-13 | B31: What could be the average size of each request?
A32: Ques-14 | B32: What is the expected user growth "Quarter on Quarter"?
A33: Ques-15 | B33: Does your application require DR (Disaster Recovery) site.
... A39: Ques-21 | B39: Do you require an SMS gateway service?
A40: Detailed Questionnaire Responses
A41: Detailed Questionnaire Responses refer to comprehensive answers requires in response to a set of questions posed in a questionnaire. The aim to provide a clear understanding of your application and associated workloads. Detailed questionnaire responses are valuable for gathering specific information or making informed decisions based on the data collected.
A43: Questionnaire | E43: Answer
A44: Ques-1 | B44: What is the primary objective of moving the application/workload to National Government cloud?
A45: Ques-2 | B45: What is the application's name, and Please provide an overview of the application and its functions.
A47: Detailed Questionnaire Responses for Disaster Recovery (DR Site) **Please Ignore this Section if DR is not required**
A48: Application
A49: Ques-1 | B49: Third Party Integration with Application? If yes, please provide details.
...

Sheet ArchitectureDiagram
A1: Please Share Current (As-Is) or (To-Be) Application or Network Architecture.
A2: Please provide a network/application deployment diagram indicating the number of application, web servers, middleware, and database layers whereever applicable.

Sheet Infra Requirements
A1: Capacity Requirements (Purpose of this sheet is to get the infrastructure requirements for the application to be hosted on the cloud. This sheet will also be used to right size the applications and scale based on workload demand requirements)
A2: Compute Requirements - (Only for IaaS) Infrastructure as a Service (IaaS) is a cloud computing service model that provides virtualized computing resources
A3: Environment (Prod/Dev/Test/SIT/UAT/DR) | B3: Layer (Web/App/Database) | C3: Application Name (website Name) | D3: No of VM | E3: Operating System | F3: Operating System Version/ DB Platform Version | G3: vCPU (per VM) | H3: RAM (per VM in GB) | I3: OS Disk Size per VM (in GB) Default 100 GB - Linux 200 GB - Windows | J3: Additional Disk per VM - Block Storage (in GB) per VM | K3: IOPS Requirement Per VM (Input/Ouput Operations Per Second) | L3: DMZ/Non DMZ | M3: Remarks
A4: Prod (Do Not Delete) | B4: Bastion Host | C4: Bastion Host | D4: 1 | E4: Ubuntu | G4: 2 | H4: 8 | I4: 100 | J4: NA | L4: DMZ | M4: Bastion Host is the recommended and mandatory Access method . Hence a Line item is already added. Separate instance of Bastion for Prod,Dev/UAT , DR etc. shall be provided.
BO21: PostgreSQL | BP21: PaaS | BQ21: PaaS | BR21: PaaS | BS21: IaaS Only | BT21: PaaS | BU21: PaaS | BV21: PaaS
A22: Database Requirement (PaaS) (PaaS for DB (Platform as a Service for Databases) refers to a cloud computing service model that provides a platform specifically designed for managing and deploying databases without the need to manage the underlying hardware and software infrastructure.)
A23: Environment | B23: Database Name | C23: PaaS | D23: Application Name (website Name) | E23: Version | F23: Number/Count | G23: vCPU | H23: RAM | I23: Current DB Size in GB | J23: DB Storage Size Requirement in GB | K23: IOPS Requirement (Input/Ouput Operations Per Second) | L23: Remarks
H24: =RAM_Lookup | J24: 1000
H25: =RAM_Lookup
H26: =RAM_Lookup
H27: =RAM_Lookup
H28: =RAM_Lookup
H29: =RAM_Lookup
H30: =RAM_Lookup
H31: =RAM_Lookup
H32: =RAM_Lookup
H33: =RAM_Lookup
A35: Compute for Containers | BO35: UAT Env.
A36: Environment Cluster Name if Any | B36: Environment (Prod/Dev/Test/SIT/UAT/DR) | C36: Number of Master Nodes | D36: Number of Worker Nodes | E36: vCPU Per Node | F36: Memory Per Node | G36: OS Disk Size (in GB) Default 100 GB | H36: Additional Storage Per Cluster (Persistent Volumes) in GB | I36: NOTE | L36: Remarks | BO36: DR Env.
A43: Additional Storage Requirement | E43: Backup Requirements
A44: Environment | B44: Type of Storage | C44: Disks Size (in GB) | E44: Environment | F44: Backup Size (GB) | G44: Remarks
G45: By default, OS disk backup is mandatory for all Virtual Machine and PaaS services provisioned through NGC.
A53: Network Services
A54: Service Name | B54: Unit of measure | C54: Capacity Requirements (For Prod) | D54: Number of Connections (For Prod) | E54: Capacity Requirements (For DR) | F54: Number of Connections (For DR) | G54: Remarks
A55: Site to Site VPN | B55: Per connection / Month | G55: 1. Please specify if you are currently using NIC provided VPN. 2. Proxy will be provided for all outbound internet connection only
A56: Client to Site VPN | B56: Per connection / Month
A57: CDN** | B57: per GB/month
A58: Public IP | B58: IP/Month
A60: Do you require Common Security Services for Prod & Non Prod environment? | C60: Yes | G60: *Valid in case of Non-Production environment only.
A61: Security Services
A62: Service Name | B62: Unit of measure | C62: Capacity Requirements (For Prod) | D62: Capacity Requirements (For Staging, UAT, Dev) | E62: Capacity Requirements (For DR) | F62: Remarks | G62: Recommendations
A63: Next Gen. Firewall | B63: Throughput in Mbps | C63: Select | D63: Select | E63: Select | G63: • Mandatory network security services i.e. Firewall (NGFW) • WAF, Application load balancer & DDoS protection is recommended service for public facing applications but not mandatory.
A64: Application Load Balancer | B64: Throughput in Mbps | C64: Select | D64: Select | E64: Select
A65: Web Application Firewall | B65: Throughput in Mbps | C65: Select | D65: Select | E65: Select
A66: DDoS Layer 7 | B66: Throughput in Mbps | C66: Select | D66: Select | E66: Select
A67: Anti Malware | B67: Per License Per VM / Month | C67: The Anti-Malware & Vulnerability Scanning services are mandatory and will be included in the total count of VMs (IaaS and PaaS).
A68: Vulnerability Scanning | B68: Instance scanned / Month
A69: SSL Certificates | B69: Per Certificate / Month | C69: Select | D69: Select | E69: Select
A70: KMS | B70: No of Keys /Month
A71: HSM | B71: No of Keys /Month
...

Sheet Drived
T1: Ubuntu 22 | U1: Windows 2019 | V1: RHEL 8 | W1: 100 | X1: ='Infra Requirements'!C63 -> Select | Y1: PostgreSQL 16.7 | Z1: PostgreSQL | AA1: DBaaS | AB1: PaaS | AC1: PaaS | AD1: IaaS | AE1: PaaS | AF1: PaaS | AG1: PaaS | AH1: 4 | AI1: =AH1*8 -> 32 | AK1: 2 | AL1: 4 | AM1: 100 | AN1: ='Infra Requirements'!D63 -> Select | AO1: ='Infra Requirements'!E63 -> Select | AP1: ='Infra Requirements'!F63 -> 0 | AQ1: =IF('Infra Requirements'!B29="Redis","vCPU_Redis",IF('Infra Requirements'!B29="MongoDB","vCPU_MongoDB","vCPU_Standard")) -> vCPU_Standard | AR1: 4 | AS1: 64
T2: Ubuntu 24 | U2: Windows 2022 | V2: RHEL 9 | W2: 200 | X2: Not Required | Y2: MSSQL 2022 | Z2: MS-SQL | AG2: IaaS | AH2: 8 | AI2: =AH2*8 -> 64 | AK2: 4 | AL2: 8 | AM2: 200 | AN2: Not Required | AO2: Not Required | AP2: Not Required | AQ2: =IF('Infra Requirements'!B33="Redis","vCPU_Redis",IF('Infra Requirements'!B33="MongoDB","vCPU_MongoDB","vCPU_Standard")) -> vCPU_Standard | AR2: 8 | AS2: 128
T3: Others, Put in Remarks | U3: =$T$3 -> Others, Put in Remarks | V3: Others, Put in Remarks | Y3: MySQL 8.0.32 | Z3: MYSQL | AH3: 16 | AI3: =AH3*8 -> 128 | AK3: 8 | AL3: 16 | AM3: 500 | AR3: 16 | AS3: 256
Y4: Latest Version | Z4: MongoDB | AH4: 24 | AI4: =AH4*8 -> 192 | AK4: 12 | AL4: 8 | AM4: 1000 | AQ4: =IF('Infra Requirements'!$C$60="No","Bandwidth_List","Blank_List") -> Blank_List | AR4: Select
Z5: Redis | AH5: 32 | AI5: =AH5*8 -> 256 | AK5: 16 | AL5: 16 | AM5: 2000 | AR5: 50 Mbps
AH6: 60 | AI6: =AH6*8 -> 480 | AK6: 24 | AL6: 32 | AR6: 100 Mbps
AK7: 32 | AL7: 16 | AR7: 200 Mbps
AK8: 60 | AL8: 32 | AR8: 300 Mbps
AK9: 64 | AL9: 64 | AR9: 400 Mbps
AL10: 24 | AR10: 500 Mbps
AL11: 48 | AR11: 600 Mbps
AL12: 96 | AR12: 700 Mbps
AL13: 32 | AR13: 800 Mbps
AL14: 64 | AR14: 900 Mbps
AL15: 128 | AR15: 1 Gbps
AL16: 48 | AR16: 2 Gbps
AL17: 96 | AR17: 3 Gbps
AL18: 192 | AR18: 4 Gbps
AL19: 64 | AR19: 5 Gbps
AL20: 128 | AR20: Above 5 Gbps
AL21: 256
AL22: 480
AL23: 128
AL24: 256
